Workbook

Sheet SMI Expanded Portfolio
A1: Security ID | B1: Company | C1: Ticker | D1: Index | E1: Sector | F1: Canton | G1: ISIN | H1: Price (CHF) | I1: Daily Perf. | J1: 3M Perf. | K1: 6M Perf. | L1: 1Y Perf. | M1: Momentum Score | N1: Signal | O1: Market Data Date | P1: Data Coverage | Q1: Source URL
A2: SEC-001 | B2: Novartis AG | C2: NOVN | D2: SMI | E2: Health care | F2: Basel | G2: CH0012005267 | H2: 123.74 | I2: -0.0072 | J2: 0.0636 | K2: -0.0254 | L2: 0.2471 | M2: =IF(COUNT(I2:L2)=0,"",I2*0.05+J2*0.2+K2*0.3+L2*0.45) -> 0.115935 | N2: =IF(M2="","Data missing",IF(M2>=20,"Positive",IF(M2<=-10,"Negative","Mixed"))) -> Mixed | O2: 28.08.2026 | P2: Complete market snapshot | Q2: https://www.finanzen.ch/index/liste/smi_expanded
A3: SEC-002 | B3: Roche Holding AG | C3: RO | D3: SMI | E3: Health care | F3: Basel | G3: CH1499059983 | H3: 358.7 | I3: -0.0146 | J3: 0.113 | K3: 0.0035 | L3: 0.4025 | M3: =IF(COUNT(I3:L3)=0,"",I3*0.05+J3*0.2+K3*0.3+L3*0.45) -> 0.204045 | N3: =IF(M3="","Data missing",IF(M3>=20,"Positive",IF(M3<=-10,"Negative","Mixed"))) -> Mixed | O3: 28.08.2026 | P3: Complete market snapshot | Q3: https://www.finanzen.ch/index/liste/smi_expanded
A4: SEC-003 | B4: Roche Holding AG | C4: ROP | D4: SMI MID | E4: Health care | F4: Basel | G4: CH0012032113 | H4: 366 | I4: -0.0203 | J4: 0.1149 | K4: -0.0149 | L4: 0.3632 | M4: =IF(COUNT(I4:L4)=0,"",I4*0.05+J4*0.2+K4*0.3+L4*0.45) -> 0.180935 | N4: =IF(M4="","Data missing",IF(M4>=20,"Positive",IF(M4<=-10,"Negative","Mixed"))) -> Mixed | O4: 28.08.2026 | P4: Complete market snapshot | Q4: https://www.finanzen.ch/index/liste/smi_expanded
A5: SEC-004 | B5: Nestlé SA | C5: NESN | D5: SMI | E5: Retail staples | F5: Vaud | G5: CH0038863350 | H5: 78.62 | I5: 0.0013 | J5: -0.0148 | K5: -0.0489 | L5: 0.0771 | M5: =IF(COUNT(I5:L5)=0,"",I5*0.05+J5*0.2+K5*0.3+L5*0.45) -> 0.01713 | N5: =IF(M5="","Data missing",IF(M5>=20,"Positive",IF(M5<=-10,"Negative","Mixed"))) -> Mixed | O5: 28.08.2026 | P5: Complete market snapshot | Q5: https://www.finanzen.ch/index/liste/smi_expanded
A6: SEC-005 | B6: ABB Ltd | C6: ABBN | D6: SMI | E6: Industrials | F6: Zurich | G6: CH0012221716 | H6: 80.1 | I6: 0.0103 | J6: -0.0476 | K6: 0.1097 | L6: 0.4814 | M6: =IF(COUNT(I6:L6)=0,"",I6*0.05+J6*0.2+K6*0.3+L6*0.45) -> 0.240535 | N6: =IF(M6="","Data missing",IF(M6>=20,"Positive",IF(M6<=-10,"Negative","Mixed"))) -> Mixed | O6: 28.08.2026 | P6: Complete market snapshot | Q6: https://www.finanzen.ch/index/liste/smi_expanded
A7: SEC-006 | B7: UBS Group AG | C7: UBSG | D7: SMI | E7: Financials | F7: Zurich/Basel | G7: CH0244767585 | H7: 44.53 | I7: 0.0167 | J7: 0.1855 | K7: 0.3714 | L7: 0.3575 | M7: =IF(COUNT(I7:L7)=0,"",I7*0.05+J7*0.2+K7*0.3+L7*0.45) -> 0.31023 | N7: =IF(M7="","Data missing",IF(M7>=20,"Positive",IF(M7<=-10,"Negative","Mixed"))) -> Mixed | O7: 28.08.2026 | P7: Complete market snapshot | Q7: https://www.finanzen.ch/index/liste/smi_expanded
A8: SEC-007 | B8: Compagnie Financière Richemont SA | C8: CFR | D8: SMI | E8: Retail discretionary | F8: Geneva | G8: CH0210483332 | H8: 194.55 | I8: 0.0183 | J8: 0.1523 | K8: 0.2146 | L8: 0.3746 | M8: =IF(COUNT(I8:L8)=0,"",I8*0.05+J8*0.2+K8*0.3+L8*0.45) -> 0.264325 | N8: =IF(M8="","Data missing",IF(M8>=20,"Positive",IF(M8<=-10,"Negative","Mixed"))) -> Mixed | O8: 28.08.2026 | P8: Complete market snapshot | Q8: https://www.finanzen.ch/index/liste/smi_expanded
A9: SEC-008 | B9: Zurich Insurance Group AG | C9: ZURN | D9: SMI | E9: Financials | F9: Zurich | G9: CH0011075394 | H9: 593.8 | I9: 0.0051 | J9: 0.0525 | K9: 0.0296 | L9: 0.0293 | M9: =IF(COUNT(I9:L9)=0,"",I9*0.05+J9*0.2+K9*0.3+L9*0.45) -> 0.03282 | N9: =IF(M9="","Data missing",IF(M9>=20,"Positive",IF(M9<=-10,"Negative","Mixed"))) -> Mixed | O9: 28.08.2026 | P9: Complete market snapshot | Q9: https://www.finanzen.ch/index/liste/smi_expanded
A10: SEC-009 | B10: Holcim Ltd | C10: HOLN | D10: SMI | E10: Materials | F10: St. Gallen | G10: CH0012214059 | H10: 73.02 | I10: 0.0036 | J10: -0.0393 | K10: 0.0412 | L10: 0.1098 | M10: =IF(COUNT(I10:L10)=0,"",I10*0.05+J10*0.2+K10*0.3+L10*0.45) -> 0.05409 | N10: =IF(M10="","Data missing",IF(M10>=20,"Positive",IF(M10<=-10,"Negative","Mixed"))) -> Mixed | O10: 28.08.2026 | P10: Complete market snapshot | Q10: https://www.finanzen.ch/index/liste/smi_expanded
A11: SEC-010 | B11: Lonza Group AG | C11: LONN | D11: SMI | E11: Health care | F11: Basel | G11: CH0013841017 | H11: 583.8 | I11: -0.0078 | J11: 0.1832 | K11: 0.0962 | L11: 0.0269 | M11: =IF(COUNT(I11:L11)=0,"",I11*0.05+J11*0.2+K11*0.3+L11*0.45) -> 0.077215 | N11: =IF(M11="","Data missing",IF(M11>=20,"Positive",IF(M11<=-10,"Negative","Mixed"))) -> Mixed | O11: 28.08.2026 | P11: Complete market snapshot | Q11: https://www.finanzen.ch/index/liste/smi_expanded
A12: SEC-011 | B12: Swiss Re Ltd | C12: SREN | D12: SMI | E12: Financials | F12: Zurich | G12: CH0126881561 | H12: 141.15 | I12: 0.0086 | J12: 0.1803 | K12: 0.0375 | L12: -0.0272 | M12: =IF(COUNT(I12:L12)=0,"",I12*0.05+J12*0.2+K12*0.3+L12*0.45) -> 0.0355 | N12: =IF(M12="","Data missing",IF(M12>=20,"Positive",IF(M12<=-10,"Negative","Mixed"))) -> Mixed | O12: 28.08.2026 | P12: Complete market snapshot | Q12: https://www.finanzen.ch/index/liste/smi_expanded
A13: SEC-012 | B13: Givaudan SA | C13: GIVN | D13: SMI | E13: Retail discretionary | F13: Geneva | G13: CH0010645932 | H13: 3322 | I13: 0.0147 | J13: 0.1485 | K13: 0.0909 | L13: -0.0018 | M13: =IF(COUNT(I13:L13)=0,"",I13*0.05+J13*0.2+K13*0.3+L13*0.45) -> 0.056895 | N13: =IF(M13="","Data missing",IF(M13>=20,"Positive",IF(M13<=-10,"Negative","Mixed"))) -> Mixed | O13: 28.08.2026 | P13: Complete market snapshot | Q13: https://www.finanzen.ch/index/liste/smi_expanded
... A21: SEC-020 | B21: Logitech International SA | C21: LOGN | D21: SMI | E21: Information technology | F21: Vaud | G21: CH0025751329 | H21: 79.88 | I21: 0.0086 | J21: -0.0765 | K21: 0.1285 | L21: -0.0317 | M21: =IF(COUNT(I21:L21)=0,"",I21*0.05+J21*0.2+K21*0.3+L21*0.45) -> 0.009415 | N21: =IF(M21="","Data missing",IF(M21>=20,"Positive",IF(M21<=-10,"Negative","Mixed"))) -> Mixed | O21: 28.08.2026 | P21: Complete market snapshot | Q21: https://www.finanzen.ch/index/liste/smi_expanded
A22: SEC-021 | B22: Amrize AG | C22: AMRZ | D22: SMI | E22: Materials | F22: Zug | M22: =IF(COUNT(I22:L22)=0,"",I22*0.05+J22*0.2+K22*0.3+L22*0.45) | N22: =IF(M22="","Data missing",IF(M22>=20,"Positive",IF(M22<=-10,"Negative","Mixed"))) -> Data missing | P22: Constituent metadata only | Q22: https://www.six-group.com/de/market-data/indices/switzerland/equity/smi-expanded-smim.html
A23: SEC-022 | B23: Galderma SA | C23: GALD | D23: SMI MID | E23: Health care | F23: Zug | M23: =IF(COUNT(I23:L23)=0,"",I23*0.05+J23*0.2+K23*0.3+L23*0.45) | N23: =IF(M23="","Data missing",IF(M23>=20,"Positive",IF(M23<=-10,"Negative","Mixed"))) -> Data missing | P23: Constituent metadata only | Q23: https://www.six-group.com/de/market-data/indices/switzerland/equity/smi-expanded-smim.html
A24: SEC-023 | B24: Sandoz Group AG | C24: SDZ | D24: SMI MID | E24: Health care | F24: Basel | M24: =IF(COUNT(I24:L24)=0,"",I24*0.05+J24*0.2+K24*0.3+L24*0.45) | N24: =IF(M24="","Data missing",IF(M24>=20,"Positive",IF(M24<=-10,"Negative","Mixed"))) -> Data missing | P24: Constituent metadata only | Q24: https://www.six-group.com/de/market-data/indices/switzerland/equity/smi-expanded-smim.html
A25: SEC-024 | B25: Schindler Holding Ltd | C25: SCHN | D25: SMI MID | E25: Industrials | F25: Lucerne | G25: CH0024638212 | H25: 257.5 | I25: -0.0039 | J25: 0.0218 | K25: -0.0835 | L25: -0.1088 | M25: =IF(COUNT(I25:L25)=0,"",I25*0.05+J25*0.2+K25*0.3+L25*0.45) -> -0.069845 | N25: =IF(M25="","Data missing",IF(M25>=20,"Positive",IF(M25<=-10,"Negative","Mixed"))) -> Mixed | O25: 28.08.2026 | P25: Complete market snapshot | Q25: https://www.finanzen.ch/index/liste/smi_expanded
A26: SEC-025 | B26: Schindler Holding Ltd | C26: SCHP | D26: SMI MID | E26: Industrials | F26: Lucerne | G26: CH0024638196 | H26: 264.2 | I26: -0.006 | J26: 0.0215 | K26: -0.0926 | L26: -0.1179 | M26: =IF(COUNT(I26:L26)=0,"",I26*0.05+J26*0.2+K26*0.3+L26*0.45) -> -0.076835 | N26: =IF(M26="","Data missing",IF(M26>=20,"Positive",IF(M26<=-10,"Negative","Mixed"))) -> Mixed | O26: 28.08.2026 | P26: Complete market snapshot | Q26: https://www.finanzen.ch/index/liste/smi_expanded
A27: SEC-026 | B27: Chocoladefabriken Lindt & Sprüngli AG | C27: LISN | D27: SMI MID | E27: Retail staples | F27: Zurich | G27: CH0010570759 | H27: 90300 | I27: -0.0259 | J27: -0.0374 | K27: -0.2697 | L27: -0.2192 | M27: =IF(COUNT(I27:L27)=0,"",I27*0.05+J27*0.2+K27*0.3+L27*0.45) -> -0.188325 | N27: =IF(M27="","Data missing",IF(M27>=20,"Positive",IF(M27<=-10,"Negative","Mixed"))) -> Mixed | O27: 28.08.2026 | P27: Complete market snapshot | Q27: https://www.finanzen.ch/index/liste/smi_expanded
A28: SEC-027 | B28: Chocoladefabriken Lindt & Sprüngli AG | C28: LISP | D28: SMI MID | E28: Retail staples | F28: Zurich | G28: CH0010570767 | H28: 8715 | I28: -0.0186 | J28: -0.0278 | K28: -0.282 | L28: -0.2481 | M28: =IF(COUNT(I28:L28)=0,"",I28*0.05+J28*0.2+K28*0.3+L28*0.45) -> -0.202735 | N28: =IF(M28="","Data missing",IF(M28>=20,"Positive",IF(M28<=-10,"Negative","Mixed"))) -> Mixed | O28: 28.08.2026 | P28: Complete market snapshot | Q28: https://www.finanzen.ch/index/liste/smi_expanded
A29: SEC-028 | B29: VAT Group | C29: VACN | D29: SMI MID | E29: Industrials | F29: St. Gallen | G29: CH0311864901 | H29: 603.2 | I29: -0.0049 | J29: 0.0063 | K29: 0.118 | L29: 1.2467 | M29: =IF(COUNT(I29:L29)=0,"",I29*0.05+J29*0.2+K29*0.3+L29*0.45) -> 0.59743 | N29: =IF(M29="","Data missing",IF(M29>=20,"Positive",IF(M29<=-10,"Negative","Mixed"))) -> Mixed | O29: 28.08.2026 | P29: Complete market snapshot | Q29: https://www.finanzen.ch/index/liste/smi_expanded
A30: SEC-029 | B30: Helvetia Baloise | C30: HBAN | D30: SMI MID | E30: Financials | F30: Basel | G30: CH0466642201 | H30: 214.8 | I30: 0.0075 | J30: 0.0329 | K30: 0.067 | L30: 0.0269 | M30: =IF(COUNT(I30:L30)=0,"",I30*0.05+J30*0.2+K30*0.3+L30*0.45) -> 0.03916 | N30: =IF(M30="","Data missing",IF(M30>=20,"Positive",IF(M30<=-10,"Negative","Mixed"))) -> Mixed | O30: 28.08.2026 | P30: Complete market snapshot | Q30: https://www.finanzen.ch/index/liste/smi_expanded
A31: SEC-030 | B31: SGS AG | C31: SGSN | D31: SMI MID | E31: Industrials | F31: Geneva | G31: CH1256740924 | H31: 93.44 | I31: 0.0013 | J31: 0.0491 | K31: -0.0353 | L31: 0.1398 | M31: =IF(COUNT(I31:L31)=0,"",I31*0.05+J31*0.2+K31*0.3+L31*0.45) -> 0.062205 | N31: =IF(M31="","Data missing",IF(M31>=20,"Positive",IF(M31<=-10,"Negative","Mixed"))) -> Mixed | O31: 28.08.2026 | P31: Complete market snapshot | Q31: https://www.finanzen.ch/index/liste/smi_expanded
A32: SEC-031 | B32: Straumann Group | C32: STMN | D32: SMI MID | E32: Health care | F32: Basel | G32: CH1175448666 | H32: 93.2 | I32: 0.0111 | J32: 0.0207 | K32: 0.003 | L32: -0.0171 | M32: =IF(COUNT(I32:L32)=0,"",I32*0.05+J32*0.2+K32*0.3+L32*0.45) -> -0.0021 | N32: =IF(M32="","Data missing",IF(M32>=20,"Positive",IF(M32<=-10,"Negative","Mixed"))) -> Mixed | O32: 28.08.2026 | P32: Complete market snapshot | Q32: https://www.finanzen.ch/index/liste/smi_expanded
A33: SEC-032 | B33: Ems-Chemie Holding AG | C33: EMSN | D33: SMI MID | E33: Materials | F33: Schwyz | G33: CH0016440353 | H33: 791 | I33: 0.0286 | J33: 0.1046 | K33: 0.2066 | L33: 0.2425 | M33: =IF(COUNT(I33:L33)=0,"",I33*0.05+J33*0.2+K33*0.3+L33*0.45) -> 0.193455 | N33: =IF(M33="","Data missing",IF(M33>=20,"Positive",IF(M33<=-10,"Negative","Mixed"))) -> Mixed | O33: 28.08.2026 | P33: Complete market snapshot | Q33: https://www.finanzen.ch/index/liste/smi_expanded
A34: SEC-033 | B34: Julius Baer Group Ltd. | C34: BAER | D34: SMI MID | E34: Financials | F34: Zurich | G34: CH0102484968 | H34: 76.06 | I34: 0.0074 | J34: 0.174 | K34: 0.15 | L34: 0.2834 | M34: =IF(COUNT(I34:L34)=0,"",I34*0.05+J34*0.2+K34*0.3+L34*0.45) -> 0.2077 | N34: =IF(M34="","Data missing",IF(M34>=20,"Positive",IF(M34<=-10,"Negative","Mixed"))) -> Mixed | O34: 28.08.2026 | P34: Complete market snapshot | Q34: https://www.finanzen.ch/index/liste/smi_expanded
A35: SEC-034 | B35: Sonova Holding AG | C35: SOON | D35: SMI MID | E35: Health care | F35: Zurich | G35: CH0012549785 | H35: 234.4 | I35: -0.0101 | J35: 0.1486 | K35: 0.1947 | L35: 0.0519 | M35: =IF(COUNT(I35:L35)=0,"",I35*0.05+J35*0.2+K35*0.3+L35*0.45) -> 0.11098 | N35: =IF(M35="","Data missing",IF(M35>=20,"Positive",IF(M35<=-10,"Negative","Mixed"))) -> Mixed | O35: 28.08.2026 | P35: Complete market snapshot | Q35: https://www.finanzen.ch/index/liste/smi_expanded
A36: SEC-035 | B36: Belimo Holding AG | C36: BEAN | D36: SMI MID | E36: Industrials | F36: Zurich | G36: CH1101098163 | H36: 878.5 | I36: 0.0221 | J36: 0.0209 | K36: 0.0777 | L36: -0.0641 | M36: =IF(COUNT(I36:L36)=0,"",I36*0.05+J36*0.2+K36*0.3+L36*0.45) -> -0.00025 | N36: =IF(M36="","Data missing",IF(M36>=20,"Positive",IF(M36<=-10,"Negative","Mixed"))) -> Mixed | O36: 28.08.2026 | P36: Complete market snapshot | Q36: https://www.finanzen.ch/index/liste/smi_expanded
... A39: SEC-038 | B39: Flughafen Zürich AG | C39: FHZN | D39: SMI MID | E39: Industrials | F39: Zurich | G39: CH0319416936 | H39: 208.2 | I39: -0.0771 | J39: -0.0017 | K39: -0.1258 | L39: -0.0633 | M39: =IF(COUNT(I39:L39)=0,"",I39*0.05+J39*0.2+K39*0.3+L39*0.45) -> -0.07042 | N39: =IF(M39="","Data missing",IF(M39>=20,"Positive",IF(M39<=-10,"Negative","Mixed"))) -> Mixed | O39: 28.08.2026 | P39: Complete market snapshot | Q39: https://www.finanzen.ch/index/liste/smi_expanded
A40: SEC-039 | B40: Accelleron AG | C40: ACLN | D40: SMI MID | E40: Industrials | F40: Aargau | M40: =IF(COUNT(I40:L40)=0,"",I40*0.05+J40*0.2+K40*0.3+L40*0.45) | N40: =IF(M40="","Data missing",IF(M40>=20,"Positive",IF(M40<=-10,"Negative","Mixed"))) -> Data missing | P40: Constituent metadata only | Q40: https://www.six-group.com/de/market-data/indices/switzerland/equity/smi-expanded-smim.html
A41: SEC-040 | B41: Avolta AG | C41: AVOL | D41: SMI MID | E41: Retail discretionary | F41: Basel-City | G41: CH0023405456 | H41: 46.2 | I41: -0.0022 | J41: -0.0088 | K41: -0.068 | L41: 0.0328 | M41: =IF(COUNT(I41:L41)=0,"",I41*0.05+J41*0.2+K41*0.3+L41*0.45) -> -0.00751 | N41: =IF(M41="","Data missing",IF(M41>=20,"Positive",IF(M41<=-10,"Negative","Mixed"))) -> Mixed | O41: 28.08.2026 | P41: Complete market snapshot | Q41: https://www.finanzen.ch/index/liste/smi_expanded
A42: SEC-041 | B42: PSP Swiss Property | C42: PSPN | D42: SMI MID | E42: Real estate | F42: Zug | G42: CH0018294154 | H42: 146.2 | I42: -0.0027 | J42: -0.0034 | K42: -0.1195 | L42: 0.0896 | M42: =IF(COUNT(I42:L42)=0,"",I42*0.05+J42*0.2+K42*0.3+L42*0.45) -> 0.003655 | N42: =IF(M42="","Data missing",IF(M42>=20,"Positive",IF(M42<=-10,"Negative","Mixed"))) -> Mixed | O42: 28.08.2026 | P42: Complete market snapshot | Q42: https://www.finanzen.ch/index/liste/smi_expanded
A43: SEC-042 | B43: Barry Callebaut AG | C43: BARN | D43: SMI MID | E43: Retail staples | F43: Zurich | G43: CH0009002962 | H43: 1107 | I43: -0.0098 | J43: -0.0674 | K43: -0.2152 | L43: 0.0883 | M43: =IF(COUNT(I43:L43)=0,"",I43*0.05+J43*0.2+K43*0.3+L43*0.45) -> -0.038795 | N43: =IF(M43="","Data missing",IF(M43>=20,"Positive",IF(M43<=-10,"Negative","Mixed"))) -> Mixed | O43: 28.08.2026 | P43: Complete market snapshot | Q43: https://www.finanzen.ch/index/liste/smi_expanded
A44: SEC-043 | B44: Swissquote Group Holding Ltd | C44: SQN | D44: SMI MID | E44: Financials | F44: Vaud | M44: =IF(COUNT(I44:L44)=0,"",I44*0.05+J44*0.2+K44*0.3+L44*0.45) | N44: =IF(M44="","Data missing",IF(M44>=20,"Positive",IF(M44<=-10,"Negative","Mixed"))) -> Data missing | P44: Constituent metadata only | Q44: https://www.six-group.com/de/market-data/indices/switzerland/equity/smi-expanded-smim.html
A45: SEC-044 | B45: SIG Group | C45: SIGN | D45: SMI MID | E45: Materials | F45: Schaffhausen | G45: CH0435377954 | H45: 13.88 | I45: -0.0007 | J45: 0.1939 | K45: 0.1214 | L45: 0.1055 | M45: =IF(COUNT(I45:L45)=0,"",I45*0.05+J45*0.2+K45*0.3+L45*0.45) -> 0.12264 | N45: =IF(M45="","Data missing",IF(M45>=20,"Positive",IF(M45<=-10,"Negative","Mixed"))) -> Mixed | O45: 28.08.2026 | P45: Complete market snapshot | Q45: https://www.finanzen.ch/index/liste/smi_expanded
A46: SEC-045 | B46: Temenos AG | C46: TEMN | D46: SMI MID | E46: Information technology | F46: Geneva | G46: CH0012453913 | H46: 75.45 | I46: -0.0118 | J46: 0.1443 | K46: 0.0483 | L46: 0.0571 | M46: =IF(COUNT(I46:L46)=0,"",I46*0.05+J46*0.2+K46*0.3+L46*0.45) -> 0.068455 | N46: =IF(M46="","Data missing",IF(M46>=20,"Positive",IF(M46<=-10,"Negative","Mixed"))) -> Mixed | O46: 28.08.2026 | P46: Complete market snapshot | Q46: https://www.finanzen.ch/index/liste/smi_expanded
A47: SEC-046 | B47: Galenica AG | C47: GALE | D47: SMI MID | E47: Health care | F47: Bern | G47: CH0360674466 | H47: 84.35 | I47: 0.0054 | J47: -0.0102 | K47: -0.1436 | L47: -0.0312 | M47: =IF(COUNT(I47:L47)=0,"",I47*0.05+J47*0.2+K47*0.3+L47*0.45) -> -0.05889 | N47: =IF(M47="","Data missing",IF(M47>=20,"Positive",IF(M47<=-10,"Negative","Mixed"))) -> Mixed | O47: 28.08.2026 | P47: Complete market snapshot | Q47: https://www.finanzen.ch/index/liste/smi_expanded
A48: SEC-047 | B48: Georg Fischer AG | C48: GF | D48: SMI MID | E48: Industrials | F48: Schaffhausen | G48: CH1169151003 | H48: 55.95 | I48: 0.0099 | J48: 0.276 | K48: 0.1562 | L48: -0.1048 | M48: =IF(COUNT(I48:L48)=0,"",I48*0.05+J48*0.2+K48*0.3+L48*0.45) -> 0.055395 | N48: =IF(M48="","Data missing",IF(M48>=20,"Positive",IF(M48<=-10,"Negative","Mixed"))) -> Mixed | O48: 28.08.2026 | P48: Complete market snapshot | Q48: https://www.finanzen.ch/index/liste/smi_expanded
A49: SEC-048 | B49: Sunrise Communications AG | C49: SUNN | D49: SMI MID | E49: Communication services | F49: Zurich | M49: =IF(COUNT(I49:L49)=0,"",I49*0.05+J49*0.2+K49*0.3+L49*0.45) | N49: =IF(M49="","Data missing",IF(M49>=20,"Positive",IF(M49<=-10,"Negative","Mixed"))) -> Data missing | P49: Constituent metadata only | Q49: https://www.six-group.com/de/market-data/indices/switzerland/equity/smi-expanded-smim.html
...

Sheet Management Summary
A1: SMI Expanded - Public Market Signal Dashboard
A2: Demo dataset for Copilot, Cowork and Copilot Studio. Not investment advice.
A4: Securities | B4: =COUNTA('SMI Expanded Portfolio'!A2:A51) -> 50
A5: With complete market snapshot | B5: =COUNT('SMI Expanded Portfolio'!H2:H51) -> 44
A6: Average 3M performance | B6: =AVERAGE('SMI Expanded Portfolio'!J2:J51) -> 0.079293182
A7: Average 6M performance | B7: =AVERAGE('SMI Expanded Portfolio'!K2:K51) -> 0.023622727
A8: Average 1Y performance | B8: =AVERAGE('SMI Expanded Portfolio'!L2:L51) -> 0.10291818
A9: Positive signals | B9: =COUNTIF('SMI Expanded Portfolio'!N2:N51,"Positive") -> 0
A10: Negative signals | B10: =COUNTIF('SMI Expanded Portfolio'!N2:N51,"Negative") -> 0
A13: Data notes
A14: The SMI itself has 20 securities. This workbook uses the SMI Expanded, which combines SMI and SMIM and contains 50 securities.
A15: Market performance values use the finanzen.ch snapshot dated 28 August 2026. Missing values remain blank and are not treated as zero.
A16: Quarterly revenue and earnings were not added because the selected index pages do not provide a consistent, comparable quarterly dataset for all 50 securities.

Sheet Demo Prompts
A1: Stage | B1: Tool | C1: Purpose | D1: English prompt
A2: 1 - AI helps | B2: Copilot in Excel | C2: Portfolio overview | D2: Analyse the SMI Expanded portfolio and identify the five securities with the strongest combined momentum across the 3-month, 6-month and 1-year performance columns. Explain the ranking and clearly flag missing data.
A3: 1 - AI helps | B3: Copilot in Excel | C3: Sector comparison | D3: Compare the average 3-month, 6-month and 1-year performance by sector. Which sectors show consistent momentum and which show mixed or negative signals?
A4: 1 - AI helps | B4: Copilot in Excel | C4: Risk and outliers | D4: Identify the largest positive and negative performance outliers. Distinguish short-term daily movements from longer-term 1-year trends.
A5: 1 - AI helps | B5: Copilot in Excel | C5: Executive summary | D5: Create an executive summary for a sales leadership team. Highlight three companies with strong public-market momentum, three companies facing visible market pressure, and the data limitations. Do not interpret stock performance as a direct sales opportunity.
A6: 2 - AI works with | B6: Cowork | C6: Account research plan | D6: Help me turn these public-market signals into an account research plan. Select three companies that warrant deeper research, explain the public signal, list the additional business information we would need, and propose responsible next steps. Do not make investment recommendations.
A7: 2 - AI works with | B7: Cowork | C7: Briefing development | D7: Create a concise executive account briefing for the selected company. Use only information from the workbook, separate facts from hypotheses, and include performance trend, sector context, open questions and a proposed discovery conversation.
A8: 2 - AI works with | B8: Copilot Studio Agent | C8: Next-best research action | D8: Which three companies should an account team research next? Use performance consistency, sector context and data completeness. For each company, provide evidence from the dataset, an open business hypothesis and the next research action.
A9: 2 - AI works with | B9: Copilot Studio Agent | C9: Watchlist | D9: Build a balanced watchlist with two positive-momentum companies, two negative-momentum companies and one mixed-signal company. Explain why each company belongs in the watchlist and avoid investment advice.
A10: 2 - AI works with | B10: Copilot Studio Agent | C10: 90-day engagement plan | D10: Create a 90-day account intelligence plan for the selected company. Include public research, stakeholder mapping, hypothesis validation, discovery preparation and governance checks. Clearly separate verified facts from assumptions.
A11: 3 - AI executes | B11: Foundry | C11: Automated monitoring | D11: Monitor new market and company-reporting signals, update the account intelligence record, detect material changes, generate a source-grounded briefing and route it to the responsible account team for human review.

Sheet Sources & Limitations
A1: Source | B1: Purpose | C1: As of | D1: URL
A2: SIX - SMI Expanded & SMIM | B2: Index definition and current constituent framework | C2: 25.09.2026 | D2: https://www.six-group.com/de/market-data/indices/switzerland/equity/smi-expanded-smim.html
A3: finanzen.ch - SMI Expanded list | B3: Prices and 3M/6M/1Y performance snapshot | C3: 28.08.2026 | D3: https://www.finanzen.ch/index/liste/smi_expanded
A4: cash.ch - SMI page | B4: User-provided starting point; SMI page does not provide 50 constituents | D4: https://www.cash.ch/aktien/smi-index-swl
A6: Important limitation
A7: This dataset is suitable for demonstrating data analysis and account-intelligence workflows. Public share-price performance should not be treated as evidence of technology demand, purchasing intent or account priority without additional validated information.
